2017-08-03T12:07:50.412825+00:00 app[web.1]: 
2017-08-03T12:07:50.412825+00:00 app[web.1]: Traceback (most recent call last):
2017-08-03T12:07:50.412826+00:00 app[web.1]:   File "/app/.heroku/python/lib/python3.6/site-packages/flask/app.py", line 1612, in full_dispatch_request
2017-08-03T12:07:50.412827+00:00 app[web.1]:     rv = self.dispatch_request()
2017-08-03T12:07:50.412827+00:00 app[web.1]:   File "/app/.heroku/python/lib/python3.6/site-packages/flask/app.py", line 1598, in dispatch_request
2017-08-03T12:07:50.412828+00:00 app[web.1]:     return self.view_functions[rule.endpoint](**req.view_args)
2017-08-03T12:07:50.412829+00:00 app[web.1]:   File "/app/.heroku/python/lib/python3.6/site-packages/flask_restful/__init__.py", line 480, in wrapper
2017-08-03T12:07:50.412829+00:00 app[web.1]:     resp = resource(*args, **kwargs)
2017-08-03T12:07:50.412831+00:00 app[web.1]:   File "/app/.heroku/python/lib/python3.6/site-packages/flask/views.py", line 84, in view
2017-08-03T12:07:50.412832+00:00 app[web.1]:     return self.dispatch_request(*args, **kwargs)
2017-08-03T12:07:50.412833+00:00 app[web.1]:   File "/app/.heroku/python/lib/python3.6/site-packages/flask_restful/__init__.py", line 595, in dispatch_request
2017-08-03T12:07:50.412833+00:00 app[web.1]:     resp = meth(*args, **kwargs)
2017-08-03T12:07:50.412834+00:00 app[web.1]:   File "/app/app/views.py", line 60, in post
2017-08-03T12:07:50.412834+00:00 app[web.1]:     if User.query.filter_by(username=args['username']).first():
2017-08-03T12:07:50.412835+00:00 app[web.1]:   File "/app/.heroku/python/lib/python3.6/site-packages/sqlalchemy/orm/query.py", line 2755, in first
2017-08-03T12:07:50.412836+00:00 app[web.1]:     ret = list(self[0:1])
2017-08-03T12:07:50.412837+00:00 app[web.1]:   File "/app/.heroku/python/lib/python3.6/site-packages/sqlalchemy/orm/query.py", line 2547, in __getitem__
2017-08-03T12:07:50.412837+00:00 app[web.1]:     return list(res)
2017-08-03T12:07:50.412838+00:00 app[web.1]:   File "/app/.heroku/python/lib/python3.6/site-packages/sqlalchemy/orm/query.py", line 2855, in __iter__
2017-08-03T12:07:50.412839+00:00 app[web.1]:     return self._execute_and_instances(context)
2017-08-03T12:07:50.412839+00:00 app[web.1]:   File "/app/.heroku/python/lib/python3.6/site-packages/sqlalchemy/orm/query.py", line 2878, in _execute_and_instances
2017-08-03T12:07:50.412840+00:00 app[web.1]:     result = conn.execute(querycontext.statement, self._params)
2017-08-03T12:07:50.412841+00:00 app[web.1]:   File "/app/.heroku/python/lib/python3.6/site-packages/sqlalchemy/engine/base.py", line 945, in execute
2017-08-03T12:07:50.412841+00:00 app[web.1]:     return meth(self, multiparams, params)
2017-08-03T12:07:50.412842+00:00 app[web.1]:   File "/app/.heroku/python/lib/python3.6/site-packages/sqlalchemy/sql/elements.py", line 263, in _execute_on_connection
2017-08-03T12:07:50.412842+00:00 app[web.1]:     return connection._execute_clauseelement(self, multiparams, params)
2017-08-03T12:07:50.412843+00:00 app[web.1]:   File "/app/.heroku/python/lib/python3.6/site-packages/sqlalchemy/engine/base.py", line 1053, in _execute_clauseelement
2017-08-03T12:07:50.412844+00:00 app[web.1]:     compiled_sql, distilled_params
2017-08-03T12:07:50.412844+00:00 app[web.1]:   File "/app/.heroku/python/lib/python3.6/site-packages/sqlalchemy/engine/base.py", line 1189, in _execute_context
2017-08-03T12:07:50.412845+00:00 app[web.1]:     context)
2017-08-03T12:07:50.412846+00:00 app[web.1]:   File "/app/.heroku/python/lib/python3.6/site-packages/sqlalchemy/engine/base.py", line 1402, in _handle_dbapi_exception
2017-08-03T12:07:50.412846+00:00 app[web.1]:     exc_info
2017-08-03T12:07:50.412847+00:00 app[web.1]:   File "/app/.heroku/python/lib/python3.6/site-packages/sqlalchemy/util/compat.py", line 203, in raise_from_cause
2017-08-03T12:07:50.412848+00:00 app[web.1]:     reraise(type(exception), exception, tb=exc_tb, cause=cause)
2017-08-03T12:07:50.412848+00:00 app[web.1]:   File "/app/.heroku/python/lib/python3.6/site-packages/sqlalchemy/util/compat.py", line 186, in reraise
2017-08-03T12:07:50.412850+00:00 app[web.1]:   File "/app/.heroku/python/lib/python3.6/site-packages/sqlalchemy/engine/base.py", line 1182, in _execute_context
2017-08-03T12:07:50.412849+00:00 app[web.1]:     raise value.with_traceback(tb)
2017-08-03T12:07:50.412850+00:00 app[web.1]:     context)
2017-08-03T12:07:50.412851+00:00 app[web.1]:   File "/app/.heroku/python/lib/python3.6/site-packages/sqlalchemy/engine/default.py", line 470, in do_execute
2017-08-03T12:07:50.412852+00:00 app[web.1]: sqlalchemy.exc.ProgrammingError: (psycopg2.ProgrammingError) relation "user" does not exist
2017-08-03T12:07:50.412853+00:00 app[web.1]: LINE 2: FROM "user" 
2017-08-03T12:07:50.412852+00:00 app[web.1]:     cursor.execute(statement, parameters)
2017-08-03T12:07:50.412853+00:00 app[web.1]:              ^
2017-08-03T12:07:50.412947+00:00 app[web.1]:  [SQL: 'SELECT "user".id AS user_id, "user".username AS user_username, "user".password AS user_password, "user".email AS user_email \nFROM "user" \nWHERE "user".username = %(username_1)s \n LIMIT %(param_1)s'] [parameters: {'username_1': 'black', 'param_1': 1}]
2017-08-03T12:08:55.669254+00:00 heroku[router]: at=info method=POST path="/auth/register" host=buckapi.herokuapp.com request_id=590d745c-896f-47c7-bfaf-5f70bdf19f39 fwd="41.209.15.146" dyno=web.1 connect=1ms service=118ms status=500 bytes=208 protocol=https
2017-08-03T12:08:55.666566+00:00 app[web.1]: [2017-08-03 12:08:55,659] ERROR in app: Exception on /auth/register [POST]
2017-08-03T12:08:55.666579+00:00 app[web.1]: Traceback (most recent call last):
2017-08-03T12:08:55.666581+00:00 app[web.1]:   File "/app/.heroku/python/lib/python3.6/site-packages/sqlalchemy/engine/base.py", line 1182, in _execute_context
2017-08-03T12:08:55.666582+00:00 app[web.1]:     context)
2017-08-03T12:08:55.666583+00:00 app[web.1]:   File "/app/.heroku/python/lib/python3.6/site-packages/sqlalchemy/engine/default.py", line 470, in do_execute
2017-08-03T12:08:55.666584+00:00 app[web.1]:     cursor.execute(statement, parameters)
2017-08-03T12:08:55.666584+00:00 app[web.1]: psycopg2.ProgrammingError: relation "user" does not exist
2017-08-03T12:08:55.666585+00:00 app[web.1]: LINE 2: FROM "user" 
2017-08-03T12:08:55.666586+00:00 app[web.1]:              ^
2017-08-03T12:08:55.666586+00:00 app[web.1]: 
2017-08-03T12:08:55.666587+00:00 app[web.1]: 
2017-08-03T12:08:55.666588+00:00 app[web.1]: The above exception was the direct cause of the following exception:
2017-08-03T12:08:55.666588+00:00 app[web.1]: 
2017-08-03T12:08:55.666589+00:00 app[web.1]: Traceback (most recent call last):
2017-08-03T12:08:55.666589+00:00 app[web.1]:   File "/app/.heroku/python/lib/python3.6/site-packages/flask/app.py", line 1612, in full_dispatch_request
2017-08-03T12:08:55.666590+00:00 app[web.1]:     rv = self.dispatch_request()
2017-08-03T12:08:55.666590+00:00 app[web.1]:   File "/app/.heroku/python/lib/python3.6/site-packages/flask/app.py", line 1598, in dispatch_request
2017-08-03T12:08:55.666591+00:00 app[web.1]:     return self.view_functions[rule.endpoint](**req.view_args)
2017-08-03T12:08:55.666592+00:00 app[web.1]:   File "/app/.heroku/python/lib/python3.6/site-packages/flask_restful/__init__.py", line 480, in wrapper
2017-08-03T12:08:55.666592+00:00 app[web.1]:     resp = resource(*args, **kwargs)
2017-08-03T12:08:55.666593+00:00 app[web.1]:   File "/app/.heroku/python/lib/python3.6/site-packages/flask/views.py", line 84, in view
2017-08-03T12:08:55.666593+00:00 app[web.1]:     return self.dispatch_request(*args, **kwargs)
2017-08-03T12:08:55.666594+00:00 app[web.1]:   File "/app/.heroku/python/lib/python3.6/site-packages/flask_restful/__init__.py", line 595, in dispatch_request
2017-08-03T12:08:55.666594+00:00 app[web.1]:     resp = meth(*args, **kwargs)
2017-08-03T12:08:55.666595+00:00 app[web.1]:   File "/app/app/views.py", line 60, in post
2017-08-03T12:08:55.666596+00:00 app[web.1]:   File "/app/.heroku/python/lib/python3.6/site-packages/sqlalchemy/orm/query.py", line 2755, in first
2017-08-03T12:08:55.666595+00:00 app[web.1]:     if User.query.filter_by(username=args['username']).first():
2017-08-03T12:08:55.666596+00:00 app[web.1]:     ret = list(self[0:1])
2017-08-03T12:08:55.666597+00:00 app[web.1]:   File "/app/.heroku/python/lib/python3.6/site-packages/sqlalchemy/orm/query.py", line 2547, in __getitem__
2017-08-03T12:08:55.666597+00:00 app[web.1]:     return list(res)
2017-08-03T12:08:55.666598+00:00 app[web.1]:   File "/app/.heroku/python/lib/python3.6/site-packages/sqlalchemy/orm/query.py", line 2855, in __iter__
2017-08-03T12:08:55.666598+00:00 app[web.1]:     return self._execute_and_instances(context)
2017-08-03T12:08:55.666599+00:00 app[web.1]:   File "/app/.heroku/python/lib/python3.6/site-packages/sqlalchemy/orm/query.py", line 2878, in _execute_and_instances
2017-08-03T12:08:55.666600+00:00 app[web.1]:     result = conn.execute(querycontext.statement, self._params)
2017-08-03T12:08:55.666600+00:00 app[web.1]:   File "/app/.heroku/python/lib/python3.6/site-packages/sqlalchemy/engine/base.py", line 945, in execute
2017-08-03T12:08:55.666601+00:00 app[web.1]:     return meth(self, multiparams, params)
2017-08-03T12:08:55.666601+00:00 app[web.1]:   File "/app/.heroku/python/lib/python3.6/site-packages/sqlalchemy/sql/elements.py", line 263, in _execute_on_connection
2017-08-03T12:08:55.666602+00:00 app[web.1]:     return connection._execute_clauseelement(self, multiparams, params)
2017-08-03T12:08:55.666602+00:00 app[web.1]:   File "/app/.heroku/python/lib/python3.6/site-packages/sqlalchemy/engine/base.py", line 1053, in _execute_clauseelement
2017-08-03T12:08:55.666603+00:00 app[web.1]:     compiled_sql, distilled_params
2017-08-03T12:08:55.666604+00:00 app[web.1]:   File "/app/.heroku/python/lib/python3.6/site-packages/sqlalchemy/engine/base.py", line 1189, in _execute_context
2017-08-03T12:08:55.666604+00:00 app[web.1]:     context)
2017-08-03T12:08:55.666605+00:00 app[web.1]:   File "/app/.heroku/python/lib/python3.6/site-packages/sqlalchemy/engine/base.py", line 1402, in _handle_dbapi_exception
2017-08-03T12:08:55.666605+00:00 app[web.1]:     exc_info
2017-08-03T12:08:55.666606+00:00 app[web.1]:   File "/app/.heroku/python/lib/python3.6/site-packages/sqlalchemy/util/compat.py", line 203, in raise_from_cause
2017-08-03T12:08:55.666606+00:00 app[web.1]:     reraise(type(exception), exception, tb=exc_tb, cause=cause)
2017-08-03T12:08:55.666607+00:00 app[web.1]:   File "/app/.heroku/python/lib/python3.6/site-packages/sqlalchemy/util/compat.py", line 186, in reraise
2017-08-03T12:08:55.666607+00:00 app[web.1]:     raise value.with_traceback(tb)
2017-08-03T12:08:55.666609+00:00 app[web.1]:   File "/app/.heroku/python/lib/python3.6/site-packages/sqlalchemy/engine/base.py", line 1182, in _execute_context
2017-08-03T12:08:55.666609+00:00 app[web.1]:     context)
2017-08-03T12:08:55.666610+00:00 app[web.1]:   File "/app/.heroku/python/lib/python3.6/site-packages/sqlalchemy/engine/default.py", line 470, in do_execute
2017-08-03T12:08:55.666610+00:00 app[web.1]:     cursor.execute(statement, parameters)
2017-08-03T12:08:55.666611+00:00 app[web.1]: sqlalchemy.exc.ProgrammingError: (psycopg2.ProgrammingError) relation "user" does not exist
2017-08-03T12:08:55.666611+00:00 app[web.1]: LINE 2: FROM "user" 
2017-08-03T12:08:55.666612+00:00 app[web.1]:              ^
2017-08-03T12:08:55.666684+00:00 app[web.1]:  [SQL: 'SELECT "user".id AS user_id, "user".username AS user_username, "user".password AS user_password, "user".email AS user_email \nFROM "user" \nWHERE "user".username = %(username_1)s \n LIMIT %(param_1)s'] [parameters: {'username_1': 'black', 'param_1': 1}]
